<?xml version="1.0" ?>
<sdf version="1.5">
  <model name="stove_table_model">
  <pose>0 0 0 0 0 0</pose>
    <link name="stove_table_link">
	  <pose>0 0 0 0 0 0</pose>
      <inertial>
        <mass>100.0</mass>
        <inertia>
          <ixx>1.0</ixx>
          <ixy>0</ixy>
          <ixz>0</ixz>
          <iyy>1.0</iyy>
          <iyz>0</iyz>
          <izz>1.0</izz>
        </inertia>
      </inertial>
      <collision name="stove_table_collision">
        <geometry>
          <mesh>
           <uri>model://stove_table/meshes/stove_table.dae</uri>
          </mesh>
        </geometry>
        <surface>
          <friction>
            <ode>
              <mu>1.0</mu>
              <mu2>1.0</mu2>
            </ode>
          </friction>
          <contact>
            <ode>
              <kp>10000000.0</kp>
              <kd>1.0</kd>
              <min_depth>0.001</min_depth>
              <max_vel>0.1</max_vel>
            </ode>
          </contact>
        </surface>
      </collision>
      <visual name="stove_table_visual">
        <geometry>
          <mesh>
           <uri>model://stove_table/meshes/stove_table.dae</uri>
          </mesh>
        </geometry>
      </visual>
    </link>

 <link name="stove_drawer_left_link">
	  <pose>-0.05 0.53 0.55 0 0 0</pose>
      <inertial>
        <mass>0.5</mass>
        <inertia>
          <ixx>0.001</ixx>
          <ixy>0</ixy>
          <ixz>0</ixz>
          <iyy>0.001</iyy>
          <iyz>0</iyz>
          <izz>0.001</izz>
        </inertia>
      </inertial>
      <collision name="stove_drawer_left_collision">
        <geometry>
          <mesh>
           <uri>model://stove_table/meshes/stove_drawer.dae</uri>
          </mesh>
        </geometry>
        <surface>
          <friction>
            <ode>
              <mu>1.0</mu>
              <mu2>1.0</mu2>
            </ode>
          </friction>
          <contact>
            <ode>
              <kp>10000000.0</kp>
              <kd>1.0</kd>
              <min_depth>0.001</min_depth>
              <max_vel>0.1</max_vel>
            </ode>
          </contact>
        </surface>
      </collision>
      <visual name="stove_drawer_left_visual">
        <geometry>
          <mesh>
           <uri>model://stove_table/meshes/stove_drawer.dae</uri>
          </mesh>
        </geometry>
      </visual>
    </link>


<link name="stove_drawer_right_link">
	  <pose>-0.05 -0.53 0.55 0 0 0</pose>
      <inertial>
        <mass>0.5</mass>
        <inertia>
          <ixx>0.001</ixx>
          <ixy>0</ixy>
          <ixz>0</ixz>
          <iyy>0.001</iyy>
          <iyz>0</iyz>
          <izz>0.001</izz>
        </inertia>
      </inertial>
      <collision name="stove_drawer_right_collision">
        <geometry>
          <mesh>
           <uri>model://stove_table/meshes/stove_drawer.dae</uri>
          </mesh>
        </geometry>
        <surface>
          <friction>
            <ode>
              <mu>1.0</mu>
              <mu2>1.0</mu2>
            </ode>
          </friction>
          <contact>
            <ode>
              <kp>10000000.0</kp>
              <kd>1.0</kd>
              <min_depth>0.001</min_depth>
              <max_vel>0.1</max_vel>
            </ode>
          </contact>
        </surface>
      </collision>
      <visual name="stove_drawer_right_visual">
        <geometry>
          <mesh>
           <uri>model://stove_table/meshes/stove_drawer.dae</uri>
          </mesh>
        </geometry>
      </visual>
    </link>


   

	<joint name="table_left_drawer_joint" type="prismatic">
		<child>stove_drawer_left_link</child>
		<parent>stove_table_link</parent>
		<axis>
			<limit>
				<lower>-0.5</lower>
				<upper>0.0</upper>
			</limit>
		<xyz>1 0 0</xyz>
		</axis>
	</joint>

	<joint name="table_right_drawer_joint" type="prismatic">
			<child>stove_drawer_right_link</child>
			<parent>stove_table_link</parent>
			<axis>
				<limit>
					<lower>-0.5</lower>
					<upper>0.0</upper>
				</limit>
			<xyz>1 0 0</xyz>
			</axis>
		</joint>

  </model>

</sdf>
